<?xml version="1.0" encoding="utf-8"?>
<robot name="borinot_flynig_arm_2">

  <link name="borinot__base_link">
    <inertial>
      <origin
        xyz="0.0 0.00244 0.0202"
        rpy="0 0 0" />
      <mass value="2.647" />
      <inertia ixx="0.027246422051605018" ixy="-0.0" ixz="0.0" iyy="0.026854677520396303" iyz="0.0" izz="0.039807168462897885" />
    </inertial>
    <visual>
      <origin xyz="0 0 0" rpy="0 0 0" />
      <geometry>
        <mesh filename="package://hidro_robots/robots/borinot_flying_arm_2/meshes/borinot__base_link.dae" />
      </geometry>
      <material name="">
        <color rgba="0.75294 0.75294 0.75294 1" />
      </material>
    </visual>
    <collision>
      <origin xyz="0 0 0" rpy="0 0 0" />
      <geometry>
        <mesh filename="package://hidro_robots/robots/borinot_flying_arm_2/meshes/borinot__base_link.dae" />
      </geometry>
    </collision>
  </link>

  <link name="flying_arm_2__link1">
    <inertial>
      <origin xyz="0.00001377 -0.07870700 -0.01935853" rpy="0 0 0" />
      <mass value="0.14853845"/>
      <inertia ixx="0.00041107" ixy="0.0" ixz="0.0" iyy="0.00003024" iyz="-0.00004671" izz="0.00041193"/>
    </inertial>
    <visual>
      <origin xyz="0 0 0" rpy="0 0 0" />
      <geometry>
        <mesh filename="package://hidro_robots/robots/borinot_flying_arm_2/meshes/flying_arm_2__link1.dae" />
      </geometry>
      <material name="">
        <color rgba="0.752941176470588 0.752941176470588 0.752941176470588 1" />
      </material>
    </visual>
    <collision>
      <origin xyz="0 0 0" rpy="0 0 0" />
      <geometry>
        <mesh filename="package://hidro_robots/robots/borinot_flying_arm_2/meshes/flying_arm_2__link1.dae" />
      </geometry>
    </collision>
  </link>

  <joint name="flying_arm_2__j_bl_link1" type="revolute">
    <origin xyz="0.064701 -0.022177 -0.05075" rpy="1.5708 0 -3.1416" />
    <parent link="borinot__base_link" />
    <child link="flying_arm_2__link1" />
    <axis xyz="0 0 -1" />
    <limit effort="2.5" lower="-1.6707963267948966" upper="1.6707963267948966" velocity="10000" />
  </joint>

  <link name="flying_arm_2__link2">
    <inertial>      
      <origin xyz="-1.39698862061666E-08 -0.12137365258327 -0.00939982619705664" rpy="0 0 0" />
      <mass value="0.0631438822022442" />
      <inertia ixx="0.000111304017624266" ixy="3.13607038597752E-11" ixz="9.25067054821333E-13" iyy="3.58195408729767E-05" iyz="-1.08459696928799E-06" izz="7.8094850616339E-05" />
    </inertial>
    <visual>
      <origin xyz="0 0 0" rpy="0 0 0" />
      <geometry>
        <mesh filename="package://hidro_robots/robots/borinot_flying_arm_2/meshes/flying_arm_2__link2.dae" />
      </geometry>
      <material name="">
        <color rgba="0.752941176470588 0.752941176470588 0.752941176470588 1" />
      </material>
    </visual>
    <collision>
      <origin xyz="0 0 0" rpy="0 0 0" />
      <geometry>
        <mesh filename="package://hidro_robots/robots/borinot_flying_arm_2/meshes/flying_arm_2__link2.dae" />
      </geometry>
    </collision>
  </link>

  <joint name="flying_arm_2__j_link1_link2" type="revolute">
    <origin xyz="0 -0.160 -0.03715" rpy="0 0 0" />
    <parent link="flying_arm_2__link1" />
    <child link="flying_arm_2__link2" />
    <axis xyz="0 0 -1" />
    <limit effort="2.5" lower="-1.6707963267948966" upper="1.6707963267948966" velocity="10000" />
  </joint>

  <link name="flying_arm_2__ee">
    <inertial>      
      <origin xyz="0 0 0" rpy="0 0 0" />
      <mass value="0.1" />
      <inertia ixx="0" ixy="0" ixz="0" iyy="0" iyz="0" izz="0" />
    </inertial>
  </link>

  <joint name="flying_arm_2__j_link2_ee" type="fixed">
    <!-- x pointing forward -->
    <origin xyz="0 -0.15 0" rpy="0 0 -1.5708" />
    <parent link="flying_arm_2__link2" />
    <child link="flying_arm_2__ee" />
    <axis xyz="0 0 -1" />
    <limit lower="0" upper="0" effort="0" velocity="0" />
  </joint>

</robot>