<?xml version="1.0"?>
<!-- =================================================================================== -->
<!-- |    This document was autogenerated by xacro from
/home/pepms/wsros2/mpc-ws/src/hidro_robots/robots/borinot_flying_arm_2/xacro/description.urdf.xacro
| -->
<!-- |    EDITING THIS FILE BY HAND IS NOT RECOMMENDED                                 | -->
<!-- =================================================================================== -->
<robot name="borinot_flying_arm_2">
  <link name="borinot__base_link">
    <inertial>
      <origin rpy="0 0 0" xyz="0.0 0.00244 0.0202" />
      <mass value="2.647" />
      <inertia ixx="0.027246422051605018" ixy="0.0" ixz="0.0" iyy="0.026854677520396303" iyz="0.0"
        izz="0.039807168462897884" />
    </inertial>
    <collision>
      <origin rpy="0 0 0" xyz="0 0 0" />
      <geometry>
        <box size="0.4 0.4 0.3" />
      </geometry>
    </collision>
    <visual>
      <origin rpy="0 0 0" xyz="0 0 0" />
      <geometry>
        <mesh filename="package://hidro_robots/robots/borinot/meshes/borinot__base_link__arm.dae"
          scale="1 1 1" />
      </geometry>
      <material name="">
        <color rgba="0.8471 0.6078 0.3412 1" />
      </material>
    </visual>
  </link>
  <link name="borinot__rotor0">
    <inertial>
      <origin rpy="0 0 0" xyz="0.0 0.0 0.0" />
      <mass value="0.005" />
      <inertia ixx="9.75e-07" ixy="0.0" ixz="0.0" iyy="0.000273104" iyz="0.0" izz="0.000274004" />
    </inertial>
    <collision>
      <origin rpy="0 0 0" xyz="0 0 0" />
      <geometry>
        <cylinder length="0.005" radius="0.070" />
      </geometry>
    </collision>
    <visual>
      <origin rpy="0 0 0" xyz="0 0 0" />
      <geometry>
        <mesh filename="package://hidro_robots/robots/common/meshes/propeller_cw.dae"
          scale="0.1 0.1 0.1" />
      </geometry>
      <material name="">
        <color rgba="0.8471 0.6078 0.3412 1" />
      </material>
    </visual>
  </link>
  <joint name="borinot__j_rotor0" type="fixed">
    <origin rpy="0.0 0 0.0" xyz="0.0 -0.185 0.05" />
    <parent link="borinot__base_link" />
    <child link="borinot__rotor0" />
    <axis xyz="0 0 1" />
    <limit effort="10" lower="-1e16" upper="1e16" velocity="1e16" />
  </joint>
  <link name="borinot__rotor1">
    <inertial>
      <origin rpy="0 0 0" xyz="0.0 0.0 0.0" />
      <mass value="0.005" />
      <inertia ixx="9.75e-07" ixy="0.0" ixz="0.0" iyy="0.000273104" iyz="0.0" izz="0.000274004" />
    </inertial>
    <collision>
      <origin rpy="0 0 0" xyz="0 0 0" />
      <geometry>
        <cylinder length="0.005" radius="0.070" />
      </geometry>
    </collision>
    <visual>
      <origin rpy="0 0 0" xyz="0 0 0" />
      <geometry>
        <mesh filename="package://hidro_robots/robots/common/meshes/propeller_ccw.dae"
          scale="0.1 0.1 0.1" />
      </geometry>
      <material name="">
        <color rgba="0.8471 0.6078 0.3412 1" />
      </material>
    </visual>
  </link>
  <joint name="borinot__j_rotor1" type="fixed">
    <origin rpy="0.0 0 0.0" xyz="0.0 0.185 0.05" />
    <parent link="borinot__base_link" />
    <child link="borinot__rotor1" />
    <axis xyz="0 0 1" />
    <limit effort="10" lower="-1e16" upper="1e16" velocity="1e16" />
  </joint>
  <link name="borinot__rotor2">
    <inertial>
      <origin rpy="0 0 0" xyz="0.0 0.0 0.0" />
      <mass value="0.005" />
      <inertia ixx="9.75e-07" ixy="0.0" ixz="0.0" iyy="0.000273104" iyz="0.0" izz="0.000274004" />
    </inertial>
    <collision>
      <origin rpy="0 0 0" xyz="0 0 0" />
      <geometry>
        <cylinder length="0.005" radius="0.070" />
      </geometry>
    </collision>
    <visual>
      <origin rpy="0 0 0" xyz="0 0 0" />
      <geometry>
        <mesh filename="package://hidro_robots/robots/common/meshes/propeller_cw.dae"
          scale="0.1 0.1 0.1" />
      </geometry>
      <material name="">
        <color rgba="0.8471 0.6078 0.3412 1" />
      </material>
    </visual>
  </link>
  <joint name="borinot__j_rotor2" type="fixed">
    <origin rpy="0.0 0 0.0" xyz="0.1602146997 0.0925 0.05" />
    <parent link="borinot__base_link" />
    <child link="borinot__rotor2" />
    <axis xyz="0 0 1" />
    <limit effort="10" lower="-1e16" upper="1e16" velocity="1e16" />
  </joint>
  <link name="borinot__rotor3">
    <inertial>
      <origin rpy="0 0 0" xyz="0.0 0.0 0.0" />
      <mass value="0.005" />
      <inertia ixx="9.75e-07" ixy="0.0" ixz="0.0" iyy="0.000273104" iyz="0.0" izz="0.000274004" />
    </inertial>
    <collision>
      <origin rpy="0 0 0" xyz="0 0 0" />
      <geometry>
        <cylinder length="0.005" radius="0.070" />
      </geometry>
    </collision>
    <visual>
      <origin rpy="0 0 0" xyz="0 0 0" />
      <geometry>
        <mesh filename="package://hidro_robots/robots/common/meshes/propeller_ccw.dae"
          scale="0.1 0.1 0.1" />
      </geometry>
      <material name="">
        <color rgba="0.8471 0.6078 0.3412 1" />
      </material>
    </visual>
  </link>
  <joint name="borinot__j_rotor3" type="fixed">
    <origin rpy="0.0 0 0.0" xyz="-0.1602146997 -0.0925 0.05" />
    <parent link="borinot__base_link" />
    <child link="borinot__rotor3" />
    <axis xyz="0 0 1" />
    <limit effort="10" lower="-1e16" upper="1e16" velocity="1e16" />
  </joint>
  <link name="borinot__rotor4">
    <inertial>
      <origin rpy="0 0 0" xyz="0.0 0.0 0.0" />
      <mass value="0.005" />
      <inertia ixx="9.75e-07" ixy="0.0" ixz="0.0" iyy="0.000273104" iyz="0.0" izz="0.000274004" />
    </inertial>
    <collision>
      <origin rpy="0 0 0" xyz="0 0 0" />
      <geometry>
        <cylinder length="0.005" radius="0.070" />
      </geometry>
    </collision>
    <visual>
      <origin rpy="0 0 0" xyz="0 0 0" />
      <geometry>
        <mesh filename="package://hidro_robots/robots/common/meshes/propeller_ccw.dae"
          scale="0.1 0.1 0.1" />
      </geometry>
      <material name="">
        <color rgba="0.8471 0.6078 0.3412 1" />
      </material>
    </visual>
  </link>
  <joint name="borinot__j_rotor4" type="fixed">
    <origin rpy="0.0 0 0.0" xyz="0.1602146997 -0.0925 0.05" />
    <parent link="borinot__base_link" />
    <child link="borinot__rotor4" />
    <axis xyz="0 0 1" />
    <limit effort="10" lower="-1e16" upper="1e16" velocity="1e16" />
  </joint>
  <link name="borinot__rotor5">
    <inertial>
      <origin rpy="0 0 0" xyz="0.0 0.0 0.0" />
      <mass value="0.005" />
      <inertia ixx="9.75e-07" ixy="0.0" ixz="0.0" iyy="0.000273104" iyz="0.0" izz="0.000274004" />
    </inertial>
    <collision>
      <origin rpy="0 0 0" xyz="0 0 0" />
      <geometry>
        <cylinder length="0.005" radius="0.070" />
      </geometry>
    </collision>
    <visual>
      <origin rpy="0 0 0" xyz="0 0 0" />
      <geometry>
        <mesh filename="package://hidro_robots/robots/common/meshes/propeller_cw.dae"
          scale="0.1 0.1 0.1" />
      </geometry>
      <material name="">
        <color rgba="0.8471 0.6078 0.3412 1" />
      </material>
    </visual>
  </link>
  <joint name="borinot__j_rotor5" type="fixed">
    <origin rpy="0.0 0 0.0" xyz="-0.1602146997 0.0925 0.05" />
    <parent link="borinot__base_link" />
    <child link="borinot__rotor5" />
    <axis xyz="0 0 1" />
    <limit effort="10" lower="-1e16" upper="1e16" velocity="1e16" />
  </joint>
  <!-- link imported from solo12, with axes properly swaped -->
  <link name="flying_arm_2__link1">
    <inertial>
      <origin rpy="0 0 0" xyz="0.00001377 -0.07870700 -0.01935853" />
      <mass value="0.14853845" />
      <inertia ixx="0.00041107" ixy="0.0" ixz="0.0" iyy="0.00003024" iyz="-0.00004671"
        izz="0.00041193" />
    </inertial>
    <visual>
      <origin rpy="0 0 0" xyz="0 0 0" />
      <geometry>
        <mesh
          filename="package://hidro_robots/robots/borinot_flying_arm_2/meshes/flying_arm_2__link1.dae" />
      </geometry>
      <material name="">
        <color rgba="0.752941176470588 0.752941176470588 0.752941176470588 1" />
      </material>
    </visual>
  </link>
  <joint name="flying_arm_2__j_bl_link1" type="revolute">
    <origin rpy="1.5708 0 -3.1416" xyz="0.064701 -0.022177 -0.05075" />
    <parent link="borinot__base_link" />
    <child link="flying_arm_2__link1" />
    <axis xyz="0 0 -1" />
    <limit effort="2.5" lower="-1.6707963267948966" upper="1.6707963267948966" velocity="10000" />
    <dynamics damping="0.0" friction="0.0" />
    <!-- <dynamics damping="0.1" friction="0.1" /> -->
  </joint>
  <!-- link with the steel m24 nut at the end -->
  <link name="flying_arm_2__link2">
    <inertial>
      <origin rpy="0 0 0" xyz="0.0 -0.1149 -0.021" />
      <mass value="0.115" />
      <inertia ixx="1.7554e-4" ixy="0.0" ixz="0.0" iyy="1.972e-5" iyz="0.0" izz="1.7938e-4" />
    </inertial>
    <visual>
      <origin rpy="0 0 0" xyz="0 0 0" />
      <geometry>
        <mesh
          filename="package://hidro_robots/robots/borinot_flying_arm_2/meshes/flying_arm_2__link2.dae" />
      </geometry>
      <material name="">
        <color rgba="0.752941176470588 0.752941176470588 0.752941176470588 1" />
      </material>
    </visual>
  </link>
  <joint name="flying_arm_2__j_link1_link2" type="revolute">
    <origin rpy="0 0 0" xyz="0 -0.160 -0.03715" />
    <parent link="flying_arm_2__link1" />
    <child link="flying_arm_2__link2" />
    <axis xyz="0 0 -1" />
    <limit effort="2.5" lower="-3.1" upper="3.1" velocity="10000" />
    <!-- <dynamics damping="0.1" friction="0.05" /> -->
    <dynamics damping="0.0" friction="0.0" />
  </joint>
  <link name="flying_arm_2__ee">
    <inertial>
      <origin rpy="0 0 0" xyz="0 0 0" />
      <mass value="0.0" />
      <inertia ixx="0" ixy="0" ixz="0" iyy="0" iyz="0" izz="0" />
    </inertial>
  </link>
  <joint name="flying_arm_2__j_link2_ee" type="fixed">
    <!-- x pointing forward -->
    <origin rpy="0 0 -1.5708" xyz="0 -0.130 0" />
    <parent link="flying_arm_2__link2" />
    <child link="flying_arm_2__ee" />
    <axis xyz="0 0 -1" />
    <limit effort="0" lower="0" upper="0" velocity="0" />
  </joint>
  <!-- <link name="payload">
    <inertial>
      <origin rpy="0 0 0" xyz="0.0 0.0 0.0" />
      <mass value="0.5" />
      <inertia ixx="8.33e-4" ixy="0.0" ixz="0.0" iyy="8.33e-4" iyz="0.0" izz="8.33e-4" />
    </inertial>
    <visual>
      <origin rpy="0 0 0" xyz="0 0 0" />
      <geometry>
        <box size="0.1 0.1 0.1"/>
      </geometry>
      <material name="">
        <color rgba="0.752941176470588 0.752941176470588 0.752941176470588 1" />
      </material>
    </visual>
  </link>
  <joint name="flying_arm_2__ee_payload" type="fixed">
    <origin rpy="0 0 0" xyz="0 0 0" />
    <parent link="flying_arm_2__ee" />
    <child link="payload" />
  </joint> -->

  <gazebo>
    <plugin filename="libeagle_gazebo_force_plugin.so" name="external_force_plugin">
      <namespace>borinot_flying_arm_2</namespace>
      <trajectoryName>aasquare.yaml</trajectoryName>
      <linkName>borinot__base_link</linkName>
      <direction>1 0 0</direction>
      <instant>1.0</instant>
      <magnitude>30.0</magnitude>
      <duration>1.0</duration>
    </plugin>
  </gazebo>
</robot>