<!-- DO NOT EDIT: Generated from iris.sdf.jinja -->
<sdf version='1.5'>
  <model name='borinot_flying_arm_2'>
    <include merge='true'>
      <uri>model://borinot</uri>
    </include>

    <joint name='flying_arm_2__j_bl_link1' type='revolute'>
      <pose relative_to='borinot__base_link'>0.06470099999999999 -0.022177 -0.05075 1.5708
        4.235164736271502e-22 3.141585307179587</pose>
      <parent>borinot__base_link</parent>
      <child>flying_arm_2__link1</child>
      <axis>
        <xyz>0 0 -1</xyz>
        <limit>
          <lower>-1.6707963267948971</lower>
          <upper>1.6707963267948971</upper>
          <effort>2.5</effort>
          <velocity>10000</velocity>
        </limit>
        <dynamics>
          <spring_reference>0</spring_reference>
          <spring_stiffness>0</spring_stiffness>
        </dynamics>
      </axis>
    </joint>
    <link name='flying_arm_2__link1'>
      <pose relative_to='flying_arm_2__j_bl_link1'>0 0 0 0 0 0</pose>
      <inertial>
        <pose>1.377e-05 -0.078707 -0.01935853 0 0 0</pose>
        <mass>0.14853844999999999</mass>
        <inertia>
          <ixx>0.00041106999999999998</ixx>
          <ixy>0</ixy>
          <ixz>0</ixz>
          <iyy>3.0239999999999998e-05</iyy>
          <iyz>-4.6709999999999998e-05</iyz>
          <izz>0.00041193000000000002</izz>
        </inertia>
      </inertial>
      <collision name='flying_arm_2__link1_collision'>
        <pose>0 -0.085 -0.02 0 0 0</pose>
        <geometry>
          <box>
            <size>0.04 0.2 0.04</size>
          </box>
        </geometry>
      </collision>
      <visual name='flying_arm_2__link1_visual'>
        <pose>0 0 0 0 0 0</pose>
        <geometry>
          <mesh>
            <scale>1 1 1</scale>
            <uri>model://borinot_flying_arm_2/meshes/flying_arm_2__link1.dae</uri>
          </mesh>
        </geometry>
        <material>
          <diffuse>0.941176 0.941176 0.941176 1</diffuse>
          <ambient>0.941176 0.941176 0.941176 1</ambient>
        </material>
      </visual>
    </link>
    <joint name='flying_arm_2__j_link1_link2' type='revolute'>
      <pose relative_to='flying_arm_2__link1'>0 -0.16 -0.03715 0 0 0</pose>
      <parent>flying_arm_2__link1</parent>
      <child>flying_arm_2__link2</child>
      <axis>
        <xyz>0 0 -1</xyz>
        <limit>
          <lower>-1.6707963267948971</lower>
          <upper>1.6707963267948971</upper>
          <effort>2.5</effort>
          <velocity>10000</velocity>
        </limit>
        <dynamics>
          <spring_reference>0</spring_reference>
          <spring_stiffness>0</spring_stiffness>
        </dynamics>
      </axis>
    </joint>
    <link name='flying_arm_2__link2'>
      <pose relative_to='flying_arm_2__j_link1_link2'>0 0 0 0 0 0</pose>
      <inertial>
        <pose>0 -0.1149 -0.021 0 0 0</pose>
        <mass>0.115</mass>
        <inertia>
          <ixx>0.0001755400000000001</ixx>
          <ixy>0</ixy>
          <ixz>0</ixz>
          <iyy>1.9720000000000021e-05</iyy>
          <iyz>-5.4210108624275222e-20</iyz>
          <izz>0.00017938000000000001</izz>
        </inertia>
      </inertial>
      <collision name='flying_arm_2__link2_collision'>
        <pose>0 -0.06 -0.01 0 0 0</pose>
        <geometry>
          <box>
            <size>0.04 0.15 0.02</size>
          </box>
        </geometry>
      </collision>
      <visual name='flying_arm_2__link2_visual'>
        <pose>0 0 0 0 0 0</pose>
        <geometry>
          <mesh>
            <scale>1 1 1</scale>
            <uri>model://borinot_flying_arm_2/meshes/flying_arm_2__link2.dae</uri>
          </mesh>
        </geometry>
        <material>
          <diffuse>0.941176 0.941176 0.941176 1</diffuse>
          <ambient>0.941176 0.941176 0.941176 1</ambient>
        </material>
      </visual>
    </link>

    <plugin
      filename="libgazebo_odri_joint_controller.so"
      name="odri_joint_controller::OdriJointController">
      <joint_name>flying_arm_2__j_bl_link1</joint_name>
      <topic_cmd>/flying_arm_2__j_bl_link1/cmd</topic_cmd>
      <topic_state>/flying_arm_2__j_bl_link1/state</topic_state>
      <motor_constant>0.025</motor_constant>
      <gear_ratio>9</gear_ratio>
      <max_current>4</max_current>
      <!-- <reverse_polarity>true</reverse_polarity> -->
      <max_velocity>80.</max_velocity>
      <lower_limit>-1.5</lower_limit>
      <upper_limit>+1.5</upper_limit>
      <kp>0.5</kp>
      <kd>5.0</kd>
      <kff>1.0</kff>
      <dt>0.001</dt>
    </plugin>

    <plugin
      filename="libgazebo_odri_joint_controller.so"
      name="odri_joint_controller::OdriJointController">
      <joint_name>flying_arm_2__j_link1_link2</joint_name>
      <topic_cmd>/flying_arm_2__j_link1_link2/cmd</topic_cmd>
      <topic_state>/flying_arm_2__j_link1_link2/state</topic_state>
      <motor_constant>0.025</motor_constant>
      <gear_ratio>9</gear_ratio>
      <max_current>4</max_current>
      <!-- <reverse_polarity>true</reverse_polarity> -->
      <max_velocity>80.</max_velocity>
      <lower_limit>-3</lower_limit>
      <upper_limit>+3</upper_limit>
      <kp>0.5</kp>
      <kd>5.0</kd>
      <kff>1.0</kff>
      <dt>0.001</dt>
    </plugin>

  </model>
</sdf>