<robot xmlns:xacro="http://www.ros.org/wiki/xacro">

  <xacro:macro name="flying_arm_2" params="simulation event_based_sim base_link_name">

    <xacro:property name="platform_name" value="borinot" />

    <xacro:if value="${base_link_name==''}">
      <link name="flying_arm_2__base_link">
        <inertial>
          <origin
            xyz="0.0 0.00244 0.0202"
            rpy="0 0 0" />
          <mass value="1.0" />
          <inertia ixx="1e-2" ixy="0.0" ixz="0.0" iyy="1e-2" iyz="0.0" izz="1e-2" />
        </inertial>
        <visual>
          <origin xyz="0 0 0" rpy="0 0 0" />
          <geometry>
            <mesh
              filename="package://hidro_robots/robots/borinot_flying_arm_2/meshes/borinot__base_link.dae" />
          </geometry>
          <material name="">
            <color rgba="0.75294 0.75294 0.75294 1" />
          </material>
        </visual>
        <gazebo>
          <static>true</static>
        </gazebo>
      </link>
    </xacro:if>

    <!-- link imported from solo12, with axes properly swaped -->
    <link name="flying_arm_2__link1">
      <inertial>
        <origin xyz="0.00001377 -0.07870700 -0.01935853" rpy="0 0 0" />
        <mass value="0.14853845" />
        <inertia ixx="0.00041107" ixy="0.0" ixz="0.0" iyy="0.00003024" iyz="-0.00004671"
          izz="0.00041193" />
      </inertial>
      <visual>
        <origin xyz="0 0 0" rpy="0 0 0" />
        <geometry>
          <mesh
            filename="package://hidro_robots/robots/borinot_flying_arm_2/meshes/flying_arm_2__link1.dae" />
        </geometry>
        <material name="">
          <color rgba="0.752941176470588 0.752941176470588 0.752941176470588 1" />
        </material>
      </visual>
    </link>

    <joint name="flying_arm_2__j_bl_link1" type="revolute">
      <origin xyz="0.064701 -0.022177 -0.05075" rpy="1.5708 0 -3.1416" />
      <xacro:if value="${base_link_name==''}">
        <parent link="flying_arm_2__base_link" />
      </xacro:if>
      <xacro:unless value="${base_link_name==''}">
        <parent link="${base_link_name}" />
      </xacro:unless>
      <child link="flying_arm_2__link1" />
      <axis xyz="0 0 -1" />
      <limit effort="2.5" lower="-1.6707963267948966" upper="1.6707963267948966" velocity="10000" />
      <dynamics damping="0.1" friction="0.1" />
    </joint>

    <!-- link with the steel m24 nut at the end -->
    <link name="flying_arm_2__link2">
      <inertial>
        <origin xyz="0.0 -0.1149 -0.021" rpy="0 0 0" />
        <mass value="0.115" />
        <inertia ixx="1.7554e-4" ixy="0.0" ixz="0.0"
          iyy="1.972e-5" iyz="0.0" izz="1.7938e-4" />
      </inertial>
      <visual>
        <origin xyz="0 0 0" rpy="0 0 0" />
        <geometry>
          <mesh
            filename="package://hidro_robots/robots/borinot_flying_arm_2/meshes/flying_arm_2__link2.dae" />
        </geometry>
        <material name="">
          <color rgba="0.752941176470588 0.752941176470588 0.752941176470588 1" />
        </material>
      </visual>
    </link>

    <joint name="flying_arm_2__j_link1_link2" type="revolute">
      <origin xyz="0 -0.160 -0.03715" rpy="0 0 0" />
      <parent link="flying_arm_2__link1" />
      <child link="flying_arm_2__link2" />
      <axis xyz="0 0 -1" />
      <limit effort="2.5" lower="-3.1" upper="3.1" velocity="10000" />
      <dynamics damping="0.1" friction="0.05" />
    </joint>

    <link name="flying_arm_2__ee">
      <inertial>
        <origin xyz="0 0 0" rpy="0 0 0" />
        <mass value="0.0" />
        <inertia ixx="0" ixy="0" ixz="0" iyy="0" iyz="0" izz="0" />
      </inertial>
    </link>

    <joint name="flying_arm_2__j_link2_ee" type="fixed">
      <!-- x pointing forward -->
      <origin xyz="0 -0.130 0" rpy="0 0 -1.5708" />
      <parent link="flying_arm_2__link2" />
      <child link="flying_arm_2__ee" />
      <axis xyz="0 0 -1" />
      <limit lower="0" upper="0" effort="0" velocity="0" />
    </joint>

    <xacro:if value="${simulation}">
      <xacro:unless value="${event_based_sim}">
        <gazebo>
          <plugin name="odri_gazebo" filename="libodri_gazebo_plugin.so">
            <joint name="flying_arm_2__j_bl_link1">
              <param name="safe_position">-1.3</param>
              <param name="safe_torque">-0.3</param>
              <param name="safe_pos_gain">2.0</param>
              <param name="safe_vel_gain">0.2</param>
            </joint>
            <joint name="flying_arm_2__j_link1_link2">
              <param name="safe_position">2.8</param>
              <param name="safe_torque">0.1</param>
              <param name="safe_pos_gain">2.0</param>
              <param name="safe_vel_gain">0.2</param>
            </joint>
          </plugin>
        </gazebo>
      </xacro:unless>
    </xacro:if>
  </xacro:macro>
</robot>